Workbook

Sheet LEIA-ME
A1: Verificação V1 do Stage C — Corpus B
A2: Gerado 2026-09-17 por stage_c/verification_v1/v1_build.py. Não edita nenhum registo; o que escreveres aqui é lido por v1_apply.py.
A4: O que é V1
A5: Abres a página citada, confirmas que a citação lá está e decides se ela sustenta o valor registado. G1/G2 (existe, página certa) já passaram por script; G3 (sustenta?) é o teu juízo. V1 não confirma ausências: essas precisam de V2 e não estão aqui.
A7: Como trabalhar
A8: 1. Filtra Tier = T1 em MEC, ADP e MODELOS. Faz T1 inteiro antes de T2–T4: é o que o Cap. 3 nomeia. T2 completa o R5 (claim_status), T3 o R6/R8, T4 o R11/R12.
A9: 2. Artigo a artigo: abre pdfs/<artigo>.V1.pdf. A capa lista os itens; cada citação está destacada na cor do tier e etiquetada com o Nº (MEC-001…). Destaques não localizados levam etiqueta vermelha no topo da página.
A10: 3. Só editas as colunas com fundo amarelo claro. Os valores vêm pré-preenchidos com o que o extractor registou: se estão certos, não mexes; se estão errados, escolhes o valor certo na lista. A célula fica laranja quando difere do registado.
A11: 4. 'Citação sustenta?' = S se a frase, lida no seu parágrafo, justifica o valor (depois da tua correção, se houve). N se não justifica nenhum valor possível; explica na Nota.
A12: 5. 'Mantém?' (MEC/ADP) = N quando a ocorrência não devia existir: não é limitação do modelo (é limitação do estudo ou barreira), duplicado, ou outro motivo na Nota.
A13: 6. 'Verificado' = S quando acabaste o item. Só os itens com S contam como V1.
A14: 7. Em Tempos, escreve os minutos por artigo. Os primeiros 3 artigos dão a estimativa real para o resto.
... A29: Cores dos tiers: T1 amarelo · T2 azul · T3 verde · T4 laranja. Célula laranja-salmão = valor alterado por ti.

Sheet Resumo
A1: Resumo da verificação V1 (fórmulas; atualiza sozinho)
A3: Folha | B3: Tier | C3: Itens | D3: Verificados | E3: % verificados | F3: Com valor alterado | G3: Citação não sustenta | H3: Retirados (Mantém? = N…)
A4: MEC | B4: T1 | C4: =COUNTIF(MEC!$B$2:$B$146,"T1") -> 72 | D4: =COUNTIFS(MEC!$B$2:$B$146,"T1",MEC!$R$2:$R$146,"S") -> 0 | E4: =IF(C4=0,"",D4/C4) -> 0 | F4: =SUMPRODUCT((MEC!$B$2:$B$146="T1")*(((MEC!$M$2:$M$146<>MEC!$S$2:$S$146)+(MEC!$N$2:$N$146<>MEC!$T$2:$T$146)+(MEC!$O$2:$O$146<>MEC!$U$2:$U$146))>0)) -> 0 | G4: =COUNTIFS(MEC!$B$2:$B$146,"T1",MEC!$L$2:$L$146,"N") -> 0 | H4: =COUNTIFS(MEC!$B$2:$B$146,"T1",MEC!$P$2:$P$146,"N*") -> 0
A5: MEC | B5: T2 | C5: =COUNTIF(MEC!$B$2:$B$146,"T2") -> 73 | D5: =COUNTIFS(MEC!$B$2:$B$146,"T2",MEC!$R$2:$R$146,"S") -> 0 | E5: =IF(C5=0,"",D5/C5) -> 0 | F5: =SUMPRODUCT((MEC!$B$2:$B$146="T2")*(((MEC!$M$2:$M$146<>MEC!$S$2:$S$146)+(MEC!$N$2:$N$146<>MEC!$T$2:$T$146)+(MEC!$O$2:$O$146<>MEC!$U$2:$U$146))>0)) -> 0 | G5: =COUNTIFS(MEC!$B$2:$B$146,"T2",MEC!$L$2:$L$146,"N") -> 0 | H5: =COUNTIFS(MEC!$B$2:$B$146,"T2",MEC!$P$2:$P$146,"N*") -> 0
A6: ADP | B6: T1 | C6: =COUNTIF(ADP!$B$2:$B$92,"T1") -> 43 | D6: =COUNTIFS(ADP!$B$2:$B$92,"T1",ADP!$T$2:$T$92,"S") -> 0 | E6: =IF(C6=0,"",D6/C6) -> 0 | F6: =SUMPRODUCT((ADP!$B$2:$B$92="T1")*(((ADP!$N$2:$N$92<>ADP!$U$2:$U$92)+(ADP!$O$2:$O$92<>ADP!$V$2:$V$92)+(ADP!$P$2:$P$92<>ADP!$W$2:$W$92)+(ADP!$Q$2:$Q$92<>ADP!$X$2:$X$92))>0)) -> 0 | G6: =COUNTIFS(ADP!$B$2:$B$92,"T1",ADP!$M$2:$M$92,"N") -> 0 | H6: =COUNTIFS(ADP!$B$2:$B$92,"T1",ADP!$R$2:$R$92,"N*") -> 0
A7: ADP | B7: T3 | C7: =COUNTIF(ADP!$B$2:$B$92,"T3") -> 48 | D7: =COUNTIFS(ADP!$B$2:$B$92,"T3",ADP!$T$2:$T$92,"S") -> 0 | E7: =IF(C7=0,"",D7/C7) -> 0 | F7: =SUMPRODUCT((ADP!$B$2:$B$92="T3")*(((ADP!$N$2:$N$92<>ADP!$U$2:$U$92)+(ADP!$O$2:$O$92<>ADP!$V$2:$V$92)+(ADP!$P$2:$P$92<>ADP!$W$2:$W$92)+(ADP!$Q$2:$Q$92<>ADP!$X$2:$X$92))>0)) -> 0 | G7: =COUNTIFS(ADP!$B$2:$B$92,"T3",ADP!$M$2:$M$92,"N") -> 0 | H7: =COUNTIFS(ADP!$B$2:$B$92,"T3",ADP!$R$2:$R$92,"N*") -> 0
A8: MODELOS | B8: T1 | C8: =COUNTIF(MODELOS!$B$2:$B$133,"T1") -> 103 | D8: =COUNTIFS(MODELOS!$B$2:$B$133,"T1",MODELOS!$P$2:$P$133,"S") -> 0 | E8: =IF(C8=0,"",D8/C8) -> 0 | F8: =SUMPRODUCT((MODELOS!$B$2:$B$133="T1")*(((MODELOS!$N$2:$N$133<>MODELOS!$Q$2:$Q$133))>0)) -> 0 | G8: =COUNTIFS(MODELOS!$B$2:$B$133,"T1",MODELOS!$M$2:$M$133,"N") -> 0 | H8: —
A9: MODELOS | B9: T4 | C9: =COUNTIF(MODELOS!$B$2:$B$133,"T4") -> 29 | D9: =COUNTIFS(MODELOS!$B$2:$B$133,"T4",MODELOS!$P$2:$P$133,"S") -> 0 | E9: =IF(C9=0,"",D9/C9) -> 0 | F9: =SUMPRODUCT((MODELOS!$B$2:$B$133="T4")*(((MODELOS!$N$2:$N$133<>MODELOS!$Q$2:$Q$133))>0)) -> 0 | G9: =COUNTIFS(MODELOS!$B$2:$B$133,"T4",MODELOS!$M$2:$M$133,"N") -> 0 | H9: —
A10: Total | C10: =SUM(C4:C9) -> 368 | D10: =SUM(D4:D9) -> 0 | E10: =IF(C10=0,"",D10/C10) -> 0 | F10: =SUM(F4:F9) -> 0 | G10: =SUM(G4:G9) -> 0

Sheet Listas
A1: effect | B1: cause | C1: claim | D1: adaptation | E1: status | F1: framing | G1: C5 data_origin | H1: C5 boundary | I1: C6 regime | J1: C7 statement | K1: C8 OOS status | L1: C13 | M1: yn | N1: keep | O1: done
A2: non-stationarity of the relationship | B2: fouling | C2: general | D2: rolling window | E2: proposed | F2: ISO 50001/50006 explicit | G2: dedicated meter | H2: exact | I2: not stated | J2: stated with numeric bounds | K2: reported | L2: yes | M2: S | N2: S | O2: S
A3: baseline drift or expiry | B3: catalyst deactivation | C3: applied to the case | D3: segmented baseline | E3: implemented | F3: implicit | G3: site meter | H3: allocated by rule | I3: explicitly none in period | J3: stated qualitatively | K3: not reported | L3: partial | M3: N | N3: N — não é limitação do modelo
A4: validity envelope exceeded | B4: feedstock quality or composition change | C4: empirically demonstrated | D4: change-point | E4: evaluated | F4: absent | G4: invoice or utility bill | H4: allocated by estimate | I4: fixed, not mentioned | J4: not stated | K4: not applicable | L4: no | N4: N — duplicado
A5: statistical misspecification | B5: product mix or grade change | D5: additional normalisation variable | G5: process historian tag | H5: mismatch acknowledged | I5: periodic, interval stated | L5: not reported | N5: N — outro (nota)
A6: observability gap — quantity not measured | B6: equipment degradation or ageing | D6: hybrid physical-statistical | G6: calculated from process data | H6: not reported | I6: event-triggered, trigger stated | L6: not applicable
A7: data quality — missing, erroneous or discontinuous data | B7: operating mode or campaign change | D7: online re-estimation | G7: laboratory assay | I7: rolling window
A8: insufficient data length for the model | B8: ambient conditions | D8: outlier exclusion | G8: simulation | I8: online or adaptive
A9: multi-product allocation | B9: plant or process modification | D9: weighted estimation | G9: not reported
A10: baseload or non-productive energy | B10: concurrent improvement programme | D10: normalisation to a reference product
A11: cross-site comparability | B11: other | D11: improved metering
A12: indicator not meaningful as defined | B12: not stated | D12: other
A13: other
A14: not stated

Sheet MEC
A1: Nº | B1: Tier | C1: Artigo | D1: Autor (ano) | E1: Pág. | F1: Pág. corrigida? | G1: ID no registo | H1: Citação | I1: support_class | J1: Other (verbatim) | K1: Localização no PDF | L1: Citação sustenta? | M1: Efeito | N1: Causa | O1: claim_status | P1: Mantém? | Q1: Nota | R1: Verificado | S1: orig_Efeito | T1: orig_Causa | U1: orig_claim_status
A2: MEC-001 | B2: T1 | C2: rayyan-472535351 | D2: Almanza (2025) | E2: 4 | G2: K1 → M1 | H2: The main assumptions adopted for the simulation model have to do with the fact that the cogeneration plant is representative of the energy and environmental performance of the refinery | I2: direct statement | J2: efeito other: model assumes the cogeneration plant is representative of the whole refinery's energy and environmental performance | K2: destacada | M2: other | N2: not stated | O2: applied to the case | S2: other | T2: not stated | U2: applied to the case
A3: MEC-003 | B3: T1 | C3: rayyan-472535351 | D3: Almanza (2025) | E3: 4 | G3: K3 → M1 | H3: natural gas is sampled from all fossil fuels used as energy sources since it is widely used and considered IEU by the refinery | I3: direct statement | J3: efeito other: only natural gas is modelled as a sample representing all fossil fuels used | K3: destacada | M3: other | N3: not stated | O3: applied to the case | S3: other | T3: not stated | U3: applied to the case
A4: MEC-002 | B4: T1 | C4: rayyan-472535351 | D4: Almanza (2025) | E4: 7 | G4: K2 → M1 | H4: Except for boiler CB5, the values returned by the model are lower than the real values. | I4: direct statement | J4: efeito other: model systematically underestimates natural gas consumption relative to real values (except one boiler) | K4: destacada | M4: other | N4: not stated | O4: empirically demonstrated | S4: other | T4: not stated | U4: empirically demonstrated
A5: MEC-004 | B5: T1 | C5: rayyan-472535351 | D5: Almanza (2025) | E5: 11 | G5: K4 → M1 | H5: these conventional indicators are absolute and can give a distorted perception of overall performance, since energy generation increases in greater proportion to the increase in fuel consumption | I5: direct statement | K5: destacada | M5: indicator not meaningful as defined | N5: not stated | O5: applied to the case | S5: indicator not meaningful as defined | T5: not stated | U5: applied to the case
A6: MEC-005 | B6: T1 | C6: rayyan-472535365 | D6: Moghadasi (2025) | E6: 10 | G6: K1 → M1 | H6: Therefore, all data recorded during startup, overhaul, etc., as well as noise points, were removed from the dataset. | I6: direct statement | J6: causa other: outliers, out-of-range data and startup/overhaul periods in the raw DCS dataset | K6: destacada | M6: data quality — missing, erroneous or discontinuous data | N6: other | O6: empirically demonstrated | S6: data quality — missing, erroneous or discontinuous data | T6: other | U6: empirically demonstrated
A7: MEC-006 | B7: T1 | C7: rayyan-472535365 | D7: Moghadasi (2025) | E7: 10 | G7: K2 → M1 | H7: At first, a multicollinearity study was accomplished in the feature selection procedure to avoid target leakage by choosing independent features. | I7: direct statement | K7: destacada | M7: statistical misspecification | N7: not stated | O7: applied to the case | S7: statistical misspecification | T7: not stated | U7: applied to the case
A8: MEC-007 | B8: T2 | C8: rayyan-472535376 | D8: Benmakhlouf (2025) | E8: 6 | G8: K1 → M1 | H8: Steam and water systems are the most complicated in the plant, as they lack the instruments needed for their proper definition. | I8: direct statement | K8: destacada | M8: observability gap — quantity not measured | N8: not stated | O8: applied to the case | S8: observability gap — quantity not measured | T8: not stated | U8: applied to the case
A9: MEC-008 | B9: T2 | C9: rayyan-472535405 | D9: Khalid (2024) | E9: 3 | G9: K1 → paper-level argument | H9: EnPIs can as effectively be identified and calculated as much detailed data is provided by the mills. | I9: direct statement | K9: destacada | M9: observability gap — quantity not measured | N9: not stated | O9: applied to the case | S9: observability gap — quantity not measured | T9: not stated | U9: applied to the case
A10: MEC-009 | B10: T2 | C10: rayyan-472535405 | D10: Khalid (2024) | E10: 6 | G10: K2 → paper-level argument | H10: The precision of the monitoring system and the efficiency of equipment/process/plants can further give detailed and accurate energy intensity. | I10: requires inference | K10: destacada | M10: data quality — missing, erroneous or discontinuous data | N10: not stated | O10: applied to the case | S10: data quality — missing, erroneous or discontinuous data | T10: not stated | U10: applied to the case
A11: MEC-010 | B11: T1 | C11: rayyan-472535480 | D11: Andersson (2021) | E11: 2 | G11: K1 → paper-level argument | H11: As the performance of production processes varies with changing conditions, such as the feedstock quality, the influence of these conditions on the developed EnPIs has to be accounted for in the analysis of the energy performance | I11: direct statement | K11: destacada | M11: non-stationarity of the relationship | N11: feedstock quality or composition change | O11: general | S11: non-stationarity of the relationship | T11: feedstock quality or composition change | U11: general
A12: MEC-011 | B12: T2 | C12: rayyan-472535480 | D12: Andersson (2021) | E12: 4 | G12: K2 → M1 | H12: Since the normal state of a mill will be unique, as it depends on factors such as technology used, chemicals used, type of end-product, raw material, etc., ‘‘the normal state’’ has to be defined individually for each mill. | I12: direct statement | K12: destacada | M12: cross-site comparability | N12: not stated | O12: applied to the case | S12: cross-site comparability | T12: not stated | U12: applied to the case
A13: MEC-014 | B13: T2 | C13: rayyan-472535480 | D13: Andersson (2021) | E13: 5 | G13: K5 → M2 | H13: the explanatory indicator is not tied to the process of which the descriptive indicators are analyzed. | I13: direct statement | K13: destacada | M13: indicator not meaningful as defined | N13: not stated | O13: applied to the case | S13: indicator not meaningful as defined | T13: not stated | U13: applied to the case
A14: MEC-012 | B14: T1 | C14: rayyan-472535480 | D14: Andersson (2021) | E14: 7 | G14: K3 → M1 | H14: This means that the mill defines multiple normal states of operation for every type of pulp quality produced, raw material used, etc. | I14: direct statement | K14: destacada | M14: non-stationarity of the relationship | N14: product mix or grade change | O14: applied to the case | S14: non-stationarity of the relationship | T14: product mix or grade change | U14: applied to the case
A15: MEC-013 | B15: T1 | C15: rayyan-472535480 | D15: Andersson (2021) | E15: 7 | G15: K4 → paper-level argument | H15: it was found that the amount of residual alkali in the black liquor had increased from 5 g/L to 9 g/L. This resulted in the larger demand of lime in the lime kiln. | I15: direct statement | K15: destacada | M15: non-stationarity of the relationship | N15: operating mode or campaign change | O15: empirically demonstrated | S15: non-stationarity of the relationship | T15: operating mode or campaign change | U15: empirically demonstrated
A16: MEC-018 | B16: T1 | C16: rayyan-472535522 | D16: Espinel-Blanco (2020) | E16: 9 | G16: K4 → A1 | H16: the burners and boilers are always operating at the same load regardless of the level of production | I16: direct statement | K16: destacada | M16: baseload or non-productive energy | N16: operating mode or campaign change | O16: empirically demonstrated | S16: baseload or non-productive energy | T16: operating mode or campaign change | U16: empirically demonstrated
A17: MEC-017 | B17: T2 | C17: rayyan-472535522 | D17: Espinel-Blanco (2020) | E17: 11 | G17: K3 → M2 | H17: the consumption of coal presents a diﬀerent behavior to the production, showing that these variations of consumption are not associated with production but are possibly outside the optimal parameters. | I17: direct statement | K17: destacada | M17: non-stationarity of the relationship | N17: not stated | O17: empirically demonstrated | S17: non-stationarity of the relationship | T17: not stated | U17: empirically demonstrated
A18: MEC-015 | B18: T2 | C18: rayyan-472535522 | D18: Espinel-Blanco (2020) | E18: 18 | G18: K1 → M2 | H18: However, in the case of coal, this value was very low. This can be explained by the fact that there is no measurement of the steam that enters the machine. | I18: direct statement | K18: destacada | M18: observability gap — quantity not measured | N18: not stated | O18: empirically demonstrated | S18: observability gap — quantity not measured | T18: not stated | U18: empirically demonstrated
... A40: MEC-039 | B40: T1 | C40: rayyan-472535582 | D40: Morales (2018) | E40: 2 | G40: K1 → paper-level argument | H40: The energy performance of steam boilers, such as the efficiency and the evaporation ratio can decrease along time because of the poor combustion, heat transfer fouling, poor operation, and low maintenance rate. | I40: direct statement | K40: destacada | M40: non-stationarity of the relationship | N40: fouling | O40: general | S40: non-stationarity of the relationship | T40: fouling | U40: general
A41: MEC-040 | B41: T1 | C41: rayyan-472535582 | D41: Morales (2018) | E41: 5 | G41: K2 → M3 | H41: It is important to note that the low efficiency peaks of 22 January, 17 February and 20 February are associated with the random nature of the process and are not the result of variation in the energy management system. | I41: direct statement | J41: efeito other: some low-efficiency index peaks reflect random process variation rather than genuine management/energy variation; causa other: random nature of the process (random operational variation) | K41: destacada | M41: other | N41: other | O41: empirically demonstrated | S41: other | T41: other | U41: empirically demonstrated
A42: MEC-042 | B42: T2 | C42: rayyan-472535585 | D42: Pelser (2018) | E42: 23 | G42: K2 → A1 | H42: The measurement of this risk could be improved by installing more refined meters on different components of the equipment. | I42: direct statement | K42: destacada | M42: observability gap — quantity not measured | N42: not stated | O42: empirically demonstrated | S42: observability gap — quantity not measured | T42: not stated | U42: empirically demonstrated
A43: MEC-041 | B43: T1 | C43: rayyan-472535585 | D43: Pelser (2018) | E43: 25 | G43: K1 → A1 | H43: The “Clinker production” and “Total energy per clinker produced” EnPIs were not evaluated as part of this study, as the plant does not continuously produce clinker. | I43: direct statement | K43: destacada | M43: insufficient data length for the model | N43: operating mode or campaign change | O43: applied to the case | S43: insufficient data length for the model | T43: operating mode or campaign change | U43: applied to the case
A44: MEC-043 | B44: T1 | C44: rayyan-472535625 | D44: Ikeyama (2017) | E44: 5 | G44: K1 → paper-level argument | H44: when a production volume is decreased, energy consumption which does not contribute to the production volume (called as baseload) has effects on the specific energy consumption. | I44: direct statement | J44: causa other: decrease of production volume | K44: destacada | M44: baseload or non-productive energy | N44: other | O44: general | S44: baseload or non-productive energy | T44: other | U44: general
A45: MEC-044 | B45: T1 | C45: rayyan-472535625 | D45: Ikeyama (2017) | E45: 5 | G45: K2 → paper-level argument | H45: If specific energy consumption is identified as EnPI, decreasing production volume might make to cancel out the effect of energy efficiency activities, because the denominator of the specific energy consumption is the production volume. | I45: direct statement | J45: causa other: decrease of production volume | K45: destacada | M45: indicator not meaningful as defined | N45: other | O45: general | S45: indicator not meaningful as defined | T45: other | U45: general
A46: MEC-046 | B46: T1 | C46: rayyan-472535649 | D46: Ochoa (2017) | E46: 3 | G46: K2 → A1 | H46: In order to calculate an equivalent production, it is necessary to determine a value for the energy consumption as the sum of every level of production times its corresponding energy intensity for every different product, as in Eq(2). | I46: direct statement | K46: destacada | M46: multi-product allocation | N46: product mix or grade change | O46: applied to the case | S46: multi-product allocation | T46: product mix or grade change | U46: applied to the case
A47: MEC-045 | B47: T1 | C47: rayyan-472535649 | D47: Ochoa (2017) | E47: 4 | G47: K1 → A1 | H47: the application of limits of control for data of consumption of gas and production so that to exclude data considered atypical | I47: direct statement | K47: destacada | M47: data quality — missing, erroneous or discontinuous data | N47: not stated | O47: empirically demonstrated | S47: data quality — missing, erroneous or discontinuous data | T47: not stated | U47: empirically demonstrated
A48: MEC-047 | B48: T1 | C48: rayyan-472535649 | D48: Ochoa (2017) | E48: 5 | G48: K3 → M4 | H48: several peaks of high efficiency with a random behavior are evidences, by what it indicates that these peaks located in the area of efficiency energy not are result of improvements in the energy management system of the company. | I48: direct statement | K48: destacada | M48: indicator not meaningful as defined | N48: not stated | O48: empirically demonstrated | S48: indicator not meaningful as defined | T48: not stated | U48: empirically demonstrated
A49: MEC-048 | B49: T1 | C49: rayyan-472535680 | D49: Yao (2016) | E49: 7 | G49: K1 → M1 | H49: the energy baseline model is no longer suitable for estimating the current state of EnPI; the model needs to be rebuilt according to the current data. | I49: direct statement | K49: destacada | M49: baseline drift or expiry | N49: not stated | O49: applied to the case | S49: baseline drift or expiry | T49: not stated | U49: applied to the case
A50: MEC-050 | B50: T1 | C50: rayyan-472535680 | D50: Yao (2016) | E50: 7 | G50: K3 → M1 | H50: if the adjusted decision coefficient is greater than the threshold, it is considered that the model fitting is good; otherwise it is considered that the model fitting is poor; the model structure or impact factors need to be reselected. | I50: direct statement | K50: destacada | M50: statistical misspecification | N50: not stated | O50: general | S50: statistical misspecification | T50: not stated | U50: general
A51: MEC-049 | B51: T1 | C51: rayyan-472535680 | D51: Yao (2016) | E51: 8 | G51: K2 → M1 | H51: Since the cracked gas compression unit is working near the set point, it presents linear relationship between EnPI and impact factors | I51: requires inference | K51: destacada | M51: validity envelope exceeded | N51: operating mode or campaign change | O51: applied to the case | S51: validity envelope exceeded | T51: operating mode or campaign change | U51: applied to the case
A52: MEC-053 | B52: T2 | C52: rayyan-472535748 | D52: Tarasovskii (2014) | E52: 3 | G52: K3 → M1 | H52: The actual unit composition of electric power can vary quite broadly (Fig. 2). | I52: requires inference | K52: destacada | M52: indicator not meaningful as defined | N52: not stated | O52: applied to the case | S52: indicator not meaningful as defined | T52: not stated | U52: applied to the case
A53: MEC-051 | B53: T1 | C53: rayyan-472535748 | D53: Tarasovskii (2014) | E53: 4 | G53: K1 → paper-level argument | H53: existing equipment undergoes wear or is operated outside of its design regimes due to a change in production plans, i.e., the energy-efficiency indices decline | I53: direct statement | K53: destacada | M53: baseline drift or expiry | N53: equipment degradation or ageing | O53: general | S53: baseline drift or expiry | T53: equipment degradation or ageing | U53: general
A54: MEC-052 | B54: T1 | C54: rayyan-472535748 | D54: Tarasovskii (2014) | E54: 4 | G54: K2 → paper-level argument | H54: existing equipment undergoes wear or is operated outside of its design regimes due to a change in production plans, i.e., the energy-efficiency indices decline | I54: direct statement | K54: destacada | M54: baseline drift or expiry | N54: operating mode or campaign change | O54: general | S54: baseline drift or expiry | T54: operating mode or campaign change | U54: general
A55: MEC-054 | B55: T2 | C55: rayyan-472535748 | D55: Tarasovskii (2014) | E55: 4 | G55: K4 → paper-level argument | H55: Even programs in the second group, which calculate norms solely on the basis of a one-factor statistical model – the volume of production – are adequate for simple equipment. | I55: requires inference | K55: destacada | M55: statistical misspecification | N55: not stated | O55: general | S55: statistical misspecification | T55: not stated | U55: general
A56: MEC-055 | B56: T2 | C56: rayyan-472535762 | D56: Castrillón-Mendoza (2013) | E56: 4 | G56: K1 → M1 | H56: Siempre y cuando la relación entre las variables analizadas sea adecuada se considera esta ecuación como la Línea de Base Energética [4], [7-8]. | I56: direct statement | K56: destacada | M56: statistical misspecification | N56: not stated | O56: general | S56: statistical misspecification | T56: not stated | U56: general
A57: MEC-056 | B57: T1 | C57: rayyan-472535762 | D57: Castrillón-Mendoza (2013) | E57: 4 | G57: K2 → M1 | H57: Esta línea meta se traza considerando el mismo valor de la pendiente “m” de la línea base, puesto que se supone en el momento que no hay ningún cambio tecnológico sobre los equipos, áreas o procesos sobre los que se realiza el análisis [4], [7]. | I57: direct statement | K57: destacada | M57: non-stationarity of the relationship | N57: plant or process modification | O57: applied to the case | S57: non-stationarity of the relationship | T57: plant or process modification | U57: applied to the case
... A72: MEC-071 | B72: T2 | C72: rayyan-472535797 | D72: Ottermann (2011) | E72: 4 | G72: K1 → A1 | H72: Thus they are not a good indication of the electrical efficiency of a specific mill or kiln. | I72: direct statement | K72: destacada | M72: indicator not meaningful as defined | N72: not stated | O72: applied to the case | S72: indicator not meaningful as defined | T72: not stated | U72: applied to the case
A73: MEC-072 | B73: T2 | C73: rayyan-472536226 | D73: El-Maghraby (2024) | E73: 3 | G73: K1 → A1 | H73: data sets were cleaned and validated by excluding abnormal values that were outside the Safe Operating Envelope (SOE). | I73: requires inference | J73: efeito other: Model built and bounded to the Safe Operating Envelope (SOE) ranges; data outside the SOE were excluded | K73: destacada | M73: validity envelope exceeded | N73: not stated | O73: applied to the case | S73: validity envelope exceeded | T73: not stated | U73: applied to the case
A74: MEC-073 | B74: T2 | C74: rayyan-472536358 | D74: Bassetti (2025) | E74: 10 | G74: K1 → M3 | H74: Therefore, the model cannot be considered very accurate for small productions (< 200 MNm3) despite all the sites analyzed are included inside the upper and lower curves. | I74: direct statement | K74: destacada | M74: validity envelope exceeded | N74: not stated | O74: empirically demonstrated | S74: validity envelope exceeded | T74: not stated | U74: empirically demonstrated
A75: MEC-074 | B75: T2 | C75: rayyan-472536358 | D75: Bassetti (2025) | E75: 10 | G75: K2 → M3 | H75: However, the lower curve presents negative asymptotic behavior, in the very beginning. | I75: direct statement | K75: destacada | M75: statistical misspecification | N75: not stated | O75: empirically demonstrated | S75: statistical misspecification | T75: not stated | U75: empirically demonstrated
...

Sheet ADP
A1: Nº | B1: Tier | C1: Artigo | D1: Autor (ano) | E1: Pág. | F1: Pág. corrigida? | G1: ID no registo | H1: Citação | I1: support_class | J1: Other (verbatim) | K1: Mecanismos do artigo | L1: Localização no PDF | M1: Citação sustenta? | N1: Adaptação | O1: Estado | P1: Enquadramento normativo | Q1: Liga a mecanismo (K-id) | R1: Mantém? | S1: Nota | T1: Verificado | U1: orig_Adaptação | V1: orig_Estado | W1: orig_Enquadramento normativo | X1: orig_Liga a mecanismo (K-id)
A2: ADP-001 | B2: T1 | C2: rayyan-472535351 | D2: Almanza (2025) | E2: 7 | G2: D1 → M1 | H2: Emissions of CO2, CO, SO2 and NO per unit of energy generated: It is the proposed relative measure of atmospheric pollutant emissions per unit of energy generated, which most accurately shows the variation in the SEA. | I2: direct statement | K2: K1 (other); K2 (other); K3 (other); K4 (indicator not meaningful as defined) | L2: destacada | N2: additional normalisation variable | O2: proposed | P2: ISO 50001/50006 explicit | Q2: K4 | U2: additional normalisation variable | V2: proposed | W2: ISO 50001/50006 explicit | X2: K4
A3: ADP-003 | B3: T1 | C3: rayyan-472535365 | D3: Moghadasi (2025) | E3: 6 | G3: D2 → A1 | H3: In the clustering part, the whole sample points were divided into the nominal working conditions clusters utilizing the k-means algorithm since the existing data contains similar status subgroups of the EDU's operation. | I3: direct statement | K3: K1 (data quality — missing, erroneous or discontinuous data); K2 (statistical misspecification) | L3: não localizada automaticamente | N3: segmented baseline | O3: implemented | P3: implicit | U3: segmented baseline | V3: implemented | W3: implicit
A4: ADP-002 | B4: T1 | C4: rayyan-472535365 | D4: Moghadasi (2025) | E4: 10 | G4: D1 → M1 | H4: Then, the outliers and out-of-range values were filtered out from the dataset using univariate and multivariate approaches for the remaining components. | I4: direct statement | K4: K1 (data quality — missing, erroneous or discontinuous data); K2 (statistical misspecification) | L4: destacada | N4: outlier exclusion | O4: implemented | P4: implicit | Q4: K1 | U4: outlier exclusion | V4: implemented | W4: implicit | X4: K1
A5: ADP-004 | B5: T1 | C5: rayyan-472535365 | D5: Moghadasi (2025) | E5: 17 | G5: D3 → A1 | H5: As future work, other ML and optimization algorithms can be applied to quantify the energy saving potential instead of comparing the average energy consumption with the lowest energy usage of the operational modes of the unit. | I5: direct statement | J5: adaptation other: apply other ML and optimization algorithms to quantify energy-saving potential instead of comparing average with lowest energy usage | K5: K1 (data quality — missing, erroneous or discontinuous data); K2 (statistical misspecification) | L5: destacada | N5: other | O5: proposed | P5: absent | U5: other | V5: proposed | W5: absent
A6: ADP-005 | B6: T3 | C6: rayyan-472535376 | D6: Benmakhlouf (2025) | E6: 4 | G6: D1 → M1 | H6: Variable outliers during shutdowns were discarded to take into account only regular operation. | I6: direct statement | K6: K1 (observability gap — quantity not measured) | L6: destacada | N6: outlier exclusion | O6: implemented | P6: absent | U6: outlier exclusion | V6: implemented | W6: absent
A7: ADP-006 | B7: T3 | C7: rayyan-472535405 | D7: Khalid (2024) | E7: 6 | G7: D1 → paper-level argument | H7: Further, a potential tool is foreseen in the use of machine learning techniques which can better assess the various EnPIs, by using all the possible data that can link the complex production with its consumption. | I7: direct statement | J7: adaptation other: use of machine learning techniques to better assess the various EnPIs | K7: K1 (observability gap — quantity not measured); K2 (data quality — missing, erroneous or discontinuous data) | L7: destacada | N7: other | O7: proposed | P7: absent | U7: other | V7: proposed | W7: absent
A8: ADP-007 | B8: T1 | C8: rayyan-472535405 | D8: Khalid (2024) | E8: 6 | G8: D2 → paper-level argument | H8: This model i.e. Fig. 5 can be matured with the continuous monitoring and update of data from different case studies. | I8: requires inference | K8: K1 (observability gap — quantity not measured); K2 (data quality — missing, erroneous or discontinuous data) | L8: destacada | N8: online re-estimation | O8: proposed | P8: implicit | U8: online re-estimation | V8: proposed | W8: implicit
A9: ADP-009 | B9: T3 | C9: rayyan-472535480 | D9: Andersson (2021) | E9: 5 | G9: D2 → M2 | H9: At the reference mill a number of explanatory indicators that affect the descriptive indicators of the chemical recovery system (i.e., the EnPIs with purple background color in Fig. 2) have been defined (Fig. 4). | I9: direct statement | K9: K1 (non-stationarity of the relationship); K2 (cross-site comparability); K3 (non-stationarity of the relationship); K4 (non-stationarity of the relationship); K5 (indicator not meaningful as defined) | L9: destacada | N9: additional normalisation variable | O9: implemented | P9: implicit | Q9: K5 | U9: additional normalisation variable | V9: implemented | W9: implicit | X9: K5
A10: ADP-008 | B10: T3 | C10: rayyan-472535480 | D10: Andersson (2021) | E10: 7 | G10: D1 → M1 | H10: This means that the mill defines multiple normal states of operation for every type of pulp quality produced, raw material used, etc. | I10: direct statement | K10: K1 (non-stationarity of the relationship); K2 (cross-site comparability); K3 (non-stationarity of the relationship); K4 (non-stationarity of the relationship); K5 (indicator not meaningful as defined) | L10: destacada | N10: segmented baseline | O10: proposed | P10: implicit | Q10: K3 | U10: segmented baseline | V10: proposed | W10: implicit | X10: K3
A11: ADP-010 | B11: T1 | C11: rayyan-472535480 | D11: Andersson (2021) | E11: 7 | G11: D3 → M1 | H11: Preferably, it should be on an hourly basis, as changes in production are sometimes short (i.e. daily energy data will sometimes not be sufficient). | I11: direct statement | K11: K1 (non-stationarity of the relationship); K2 (cross-site comparability); K3 (non-stationarity of the relationship); K4 (non-stationarity of the relationship); K5 (indicator not meaningful as defined) | L11: destacada | N11: improved metering | O11: proposed | P11: absent | U11: improved metering | V11: proposed | W11: absent
A12: ADP-011 | B12: T1 | C12: rayyan-472535524 | D12: Beisheim (2020) | E12: 1 | G12: D1 → M1 | H12: an aggregation method is proposed to exploit the analysis of the factors on lower hierarchical layers for the evaluation of the performance of an aggregated domain. | I12: direct statement | J12: adaptation other: hierarchical bottom-up aggregation of process-level energy performance indicators and baselines to site/company level | K12: K1 (cross-site comparability); K2 (multi-product allocation); K3 (observability gap — quantity not measured); K4 (non-stationarity of the relationship); K5 (non-stationarity of the relationship); K6 (multi-product allocation) | L12: destacada | N12: other | O12: implemented | P12: ISO 50001/50006 explicit | U12: other | V12: implemented | W12: ISO 50001/50006 explicit
A13: ADP-013 | B13: T1 | C13: rayyan-472535524 | D13: Beisheim (2020) | E13: 10 | G13: D3 → M1 | H13: The concept is compatible with the usage of different types of baseline models, e.g. linear regression or artificial neural networks, in one system | I13: direct statement | J13: adaptation other: use of different baseline model types (linear regression or artificial neural networks) within one aggregation system | K13: K1 (cross-site comparability); K2 (multi-product allocation); K3 (observability gap — quantity not measured); K4 (non-stationarity of the relationship); K5 (non-stationarity of the relationship); K6 (multi-product allocation) | L13: destacada | N13: other | O13: implemented | P13: implicit | U13: other | V13: implemented | W13: implicit
A14: ADP-012 | B14: T1 | C14: rayyan-472535524 | D14: Beisheim (2020) | E14: 11 | G14: D2 → M1 | H14: splitting the performance of the plants and of the site into contributions of influenceable and non-influenceable factors. | I14: direct statement | K14: K1 (cross-site comparability); K2 (multi-product allocation); K3 (observability gap — quantity not measured); K4 (non-stationarity of the relationship); K5 (non-stationarity of the relationship); K6 (multi-product allocation) | L14: destacada | N14: additional normalisation variable | O14: implemented | P14: ISO 50001/50006 explicit | Q14: K5 | U14: additional normalisation variable | V14: implemented | W14: ISO 50001/50006 explicit | X14: K5
A15: ADP-014 | B15: T3 | C15: rayyan-472535532 | D15: Mahesthi (2020) | E15: 10 | G15: D1 → M6 | H15: Baseline determination by using single regression will be updated using other influential variables so that the use of multiple regression for new baselines will be considered. | I15: direct statement | K15: K1 (non-stationarity of the relationship); K2 (baseload or non-productive energy); K3 (baseload or non-productive energy); K4 (indicator not meaningful as defined) | L15: destacada | N15: additional normalisation variable | O15: proposed | P15: implicit | Q15: K1 | U15: additional normalisation variable | V15: proposed | W15: implicit | X15: K1
A16: ADP-017 | B16: T1 | C16: rayyan-472535550 | D16: Hamedi (2019) | E16: 1 | G16: D3 → A1 | H16: when the relative errors are taken into account, performance of ANN models appears fairly superior compared to the MLR model. | I16: direct statement | J16: adaptation other: comparison of ANN against MLR as alternative baseline models | K16: K1 (indicator not meaningful as defined); K2 (baseload or non-productive energy); K3 (statistical misspecification); K4 (statistical misspecification); K5 (observability gap — quantity not measured); K6 (observability gap — quantity not measured); K7 (data quality — missing, erroneous or discontinuous data); K8 (data quality — missing, erroneous or discontinuous data); K9 (statistical misspecification); K10 (non-stationarity of the relationship) | L16: destacada | N16: other | O16: evaluated | P16: absent | U16: other | V16: evaluated | W16: absent
A17: ADP-015 | B17: T1 | C17: rayyan-472535550 | D17: Hamedi (2019) | E17: 8 | G17: D1 → A1 | H17: after brainstorm with the LDPE engineers (EnPI Tool Instruction Guide, 2011), 8 factors were selected as independent variables (inputs) | I17: direct statement | K17: K1 (indicator not meaningful as defined); K2 (baseload or non-productive energy); K3 (statistical misspecification); K4 (statistical misspecification); K5 (observability gap — quantity not measured); K6 (observability gap — quantity not measured); K7 (data quality — missing, erroneous or discontinuous data); K8 (data quality — missing, erroneous or discontinuous data); K9 (statistical misspecification); K10 (non-stationarity of the relationship) | L17: destacada | N17: additional normalisation variable | O17: implemented | P17: implicit | U17: additional normalisation variable | V17: implemented | W17: implicit
A18: ADP-016 | B18: T1 | C18: rayyan-472535550 | D18: Hamedi (2019) | E18: 8 | G18: D2 → A1 | H18: The noisy data that belong to the days within which, the plant has been under maintenance or long-term overhaul are eliminated to decrease the errors (118 days). | I18: direct statement | K18: K1 (indicator not meaningful as defined); K2 (baseload or non-productive energy); K3 (statistical misspecification); K4 (statistical misspecification); K5 (observability gap — quantity not measured); K6 (observability gap — quantity not measured); K7 (data quality — missing, erroneous or discontinuous data); K8 (data quality — missing, erroneous or discontinuous data); K9 (statistical misspecification); K10 (non-stationarity of the relationship) | L18: destacada | N18: outlier exclusion | O18: implemented | P18: absent | Q18: K8 | U18: outlier exclusion | V18: implemented | W18: absent | X18: K8
A19: ADP-018 | B19: T1 | C19: rayyan-472535550 | D19: Hamedi (2019) | E19: 13 | G19: D4 → A1 | H19: the PCDA cycle (Plan-Do-Check-Act) should be repeated to ﬁnd the best performance and continuously upgrade the baseline. | I19: direct statement | K19: K1 (indicator not meaningful as defined); K2 (baseload or non-productive energy); K3 (statistical misspecification); K4 (statistical misspecification); K5 (observability gap — quantity not measured); K6 (observability gap — quantity not measured); K7 (data quality — missing, erroneous or discontinuous data); K8 (data quality — missing, erroneous or discontinuous data); K9 (statistical misspecification); K10 (non-stationarity of the relationship) | L19: destacada | N19: online re-estimation | O19: proposed | P19: implicit | U19: online re-estimation | V19: proposed | W19: implicit
A20: ADP-019 | B20: T1 | C20: rayyan-472535550 | D20: Hamedi (2019) | E20: 14 | G20: D5 → A1 | H20: the model could also become completed applying more advanced ANNs such as recurrent neural networks. | I20: direct statement | J20: adaptation other: more advanced ANNs such as recurrent neural networks | K20: K1 (indicator not meaningful as defined); K2 (baseload or non-productive energy); K3 (statistical misspecification); K4 (statistical misspecification); K5 (observability gap — quantity not measured); K6 (observability gap — quantity not measured); K7 (data quality — missing, erroneous or discontinuous data); K8 (data quality — missing, erroneous or discontinuous data); K9 (statistical misspecification); K10 (non-stationarity of the relationship) | L20: destacada | N20: other | O20: proposed | P20: absent | U20: other | V20: proposed | W20: absent
A21: ADP-020 | B21: T1 | C21: rayyan-472535582 | D21: Morales (2018) | E21: 5 | G21: D1 → M1 | H21: filtering of data was carried out in order to establish a more stable correlation; with the purpose of not losing functionality between production and energy when it comes to energy indicators analysis, selecting as final criteria 2 standard deviation. | I21: direct statement | K21: K1 (non-stationarity of the relationship); K2 (other) | L21: destacada | N21: outlier exclusion | O21: implemented | P21: implicit | U21: outlier exclusion | V21: implemented | W21: implicit
A22: ADP-023 | B22: T3 | C22: rayyan-472535585 | D22: Pelser (2018) | E22: 13 | G22: D3 → A1 | H22: Developing an effective budgeting system (step 7) ensures that the targets and budgets are adapted according to performance, resulting in continuous improvement and a target that is realistic, but still aims to reach the optimal performance. | I22: requires inference | K22: K1 (insufficient data length for the model); K2 (observability gap — quantity not measured) | L22: destacada | N22: rolling window | O22: implemented | P22: implicit | U22: rolling window | V22: implemented | W22: implicit
A23: ADP-021 | B23: T3 | C23: rayyan-472535585 | D23: Pelser (2018) | E23: 22 | G23: D1 → A1 | H23: tariff structures during the summer and winter months, the trend lines were generated separately for the two cases in the graphs. | I23: direct statement | K23: K1 (insufficient data length for the model); K2 (observability gap — quantity not measured) | L23: destacada | N23: segmented baseline | O23: implemented | P23: absent | U23: segmented baseline | V23: implemented | W23: absent
A24: ADP-022 | B24: T1 | C24: rayyan-472535585 | D24: Pelser (2018) | E24: 23 | G24: D2 → A1 | H24: The measurement of this risk could be improved by installing more refined meters on different components of the equipment. | I24: direct statement | K24: K1 (insufficient data length for the model); K2 (observability gap — quantity not measured) | L24: destacada | N24: improved metering | O24: proposed | P24: absent | Q24: K2 | U24: improved metering | V24: proposed | W24: absent | X24: K2
A25: ADP-024 | B25: T1 | C25: rayyan-472535585 | D25: Pelser (2018) | E25: 27 | G25: D4 → A1 | H25: To adapt this strategy the critical meters required to continuously monitor coal consumption have to be installed. | I25: direct statement | K25: K1 (insufficient data length for the model); K2 (observability gap — quantity not measured) | L25: destacada | N25: improved metering | O25: proposed | P25: absent | U25: improved metering | V25: proposed | W25: absent
A26: ADP-025 | B26: T1 | C26: rayyan-472535625 | D26: Ikeyama (2017) | E26: 5 | G26: D1 → M1 | H26: this function creates calculation models which are fitted to them and manages finely with setting the detail targets. | I26: requires inference | K26: K1 (baseload or non-productive energy); K2 (indicator not meaningful as defined) | L26: destacada | N26: online re-estimation | O26: implemented | P26: implicit | U26: online re-estimation | V26: implemented | W26: implicit
A27: ADP-026 | B27: T1 | C27: rayyan-472535625 | D27: Ikeyama (2017) | E27: 5 | G27: D2 → paper-level argument | H27: JEITA has been suggesting the indicators which can be shown | I27: requires inference | J27: adaptation other: indicators shown as 'result of efforts' (based on ISO 50006), replacing plain specific energy consumption | K27: K1 (baseload or non-productive energy); K2 (indicator not meaningful as defined) | L27: destacada | N27: other | O27: proposed | P27: ISO 50001/50006 explicit | Q27: K1 | U27: other | V27: proposed | W27: ISO 50001/50006 explicit | X27: K1
A28: ADP-028 | B28: T1 | C28: rayyan-472535649 | D28: Ochoa (2017) | E28: 3 | G28: D2 → A1 | H28: The energy relationship of the products αj, corresponds to the number of units of product base that can be elaborated with the energy used to produce a unit of product (j). | I28: direct statement | K28: K1 (data quality — missing, erroneous or discontinuous data); K2 (multi-product allocation); K3 (indicator not meaningful as defined) | L28: destacada | N28: normalisation to a reference product | O28: implemented | P28: implicit | Q28: K2 | U28: normalisation to a reference product | V28: implemented | W28: implicit | X28: K2
A29: ADP-027 | B29: T1 | C29: rayyan-472535649 | D29: Ochoa (2017) | E29: 4 | G29: D1 → A1 | H29: these data considered as outliers will not be considered for the productive plant energy analysis | I29: direct statement | K29: K1 (data quality — missing, erroneous or discontinuous data); K2 (multi-product allocation); K3 (indicator not meaningful as defined) | L29: destacada | N29: outlier exclusion | O29: implemented | P29: implicit | Q29: K1 | U29: outlier exclusion | V29: implemented | W29: implicit | X29: K1
A30: ADP-029 | B30: T1 | C30: rayyan-472535649 | D30: Ochoa (2017) | E30: 5 | G30: D3 → A1 | H30: it is necessary to develop a Software for tracking, measurement, and analysis of the energy performance for each significant use of energy installed and set in operation | I30: direct statement | J30: adaptation other: Software for tracking, measurement, and analysis of the energy performance | K30: K1 (data quality — missing, erroneous or discontinuous data); K2 (multi-product allocation); K3 (indicator not meaningful as defined) | L30: destacada | N30: other | O30: proposed | P30: implicit | U30: other | V30: proposed | W30: implicit
A31: ADP-031 | B31: T1 | C31: rayyan-472535680 | D31: Yao (2016) | E31: 4 | G31: D2 → M1 | H31: Therefore, general function forms are proposed to approximate various nonlinear relationships. The EnPIs are the sum of nonlinear relationships of each impact factor, as shown in the following: | I31: direct statement | J31: adaptation other: B-spline approximation model where each EnPI is expressed as a sum of nonlinear functions of each impact factor, each approximated by a T-order B-spline function, for strongly nonlinear processes | K31: K1 (baseline drift or expiry); K2 (validity envelope exceeded); K3 (statistical misspecification) | L31: destacada | N31: other | O31: proposed | P31: implicit | U31: other | V31: proposed | W31: implicit
A32: ADP-030 | B32: T1 | C32: rayyan-472535680 | D32: Yao (2016) | E32: 7 | G32: D1 → M1 | H32: the model needs to be rebuilt according to the current data. | I32: direct statement | K32: K1 (baseline drift or expiry); K2 (validity envelope exceeded); K3 (statistical misspecification) | L32: destacada | N32: online re-estimation | O32: proposed | P32: ISO 50001/50006 explicit | Q32: K1 | U32: online re-estimation | V32: proposed | W32: ISO 50001/50006 explicit | X32: K1
A33: ADP-032 | B33: T3 | C33: rayyan-472535748 | D33: Tarasovskii (2014) | E33: 4 | G33: D1 → M2 | H33: More complex statistical models are constructed with allowance for several influencing factors. | I33: direct statement | K33: K1 (baseline drift or expiry); K2 (baseline drift or expiry); K3 (indicator not meaningful as defined); K4 (statistical misspecification) | L33: destacada | N33: additional normalisation variable | O33: implemented | P33: implicit | Q33: K4 | U33: additional normalisation variable | V33: implemented | W33: implicit | X33: K4
A34: ADP-034 | B34: T3 | C34: rayyan-472535748 | D34: Tarasovskii (2014) | E34: 4 | G34: D3 → M3 | H34: The errors are even smaller for multi-factorial models, including those which make use of the theory of artificial neural networks or various physical models of equipment constructed on the basis of the results of tests or numerical modeling [4, 5]. | I34: direct statement | K34: K1 (baseline drift or expiry); K2 (baseline drift or expiry); K3 (indicator not meaningful as defined); K4 (statistical misspecification) | L34: destacada | N34: hybrid physical-statistical | O34: implemented | P34: implicit | Q34: K4 | U34: hybrid physical-statistical | V34: implemented | W34: implicit | X34: K4
A35: ADP-033 | B35: T1 | C35: rayyan-472535748 | D35: Tarasovskii (2014) | E35: 6 | G35: D2 → M3 | H35: runs models periodically based on a time period chosen by the user, chooses the best-performing model, and recalculates the existing norms | I35: direct statement | K35: K1 (baseline drift or expiry); K2 (baseline drift or expiry); K3 (indicator not meaningful as defined); K4 (statistical misspecification) | L35: destacada | N35: online re-estimation | O35: implemented | P35: implicit | Q35: K1 | U35: online re-estimation | V35: implemented | W35: implicit | X35: K1
A36: ADP-035 | B36: T3 | C36: rayyan-472535762 | D36: Castrillón-Mendoza (2013) | E36: 7 | G36: D1 → M3 | H36: la tecnología SGIE recomienda establecer una estructura de indicadores de desempeño energético a nivel de empresa o proceso en forma de “árbol de indicadores”, figura 7, de manera tal, que el indicador de eficiencia base 100 de la empresa sea estructurado a partir de los indicadores de eficiencia base 100 de cada uno de las áreas y equipos de uso final que lo componen. | I36: direct statement | K36: K1 (statistical misspecification); K2 (non-stationarity of the relationship); K3 (indicator not meaningful as defined) | L36: destacada | N36: segmented baseline | O36: proposed | P36: implicit | U36: segmented baseline | V36: proposed | W36: implicit
A37: ADP-036 | B37: T3 | C37: rayyan-472535762 | D37: Castrillón-Mendoza (2013) | E37: 7 | G37: D2 → A1 | H37: Como resultado se identificaron siete variables con el mayor impacto en el consumo de energía en los centros de costos críticos de clinkerización, molienda de cemento y primaria, las cuales se resumen en la tabla 3. | I37: direct statement | J37: adaptation other: identificación y estabilización de variables de control operacional por centro de costo de energía | K37: K1 (statistical misspecification); K2 (non-stationarity of the relationship); K3 (indicator not meaningful as defined) | L37: destacada | N37: other | O37: implemented | P37: implicit | U37: other | V37: implemented | W37: implicit
A38: ADP-037 | B38: T1 | C38: rayyan-472535787 | D38: González (2012) | E38: 10 | G38: D1 → M1 | H38: analysis of the causes of deviations, reporting of results, and finally, the modification of target lines. | I38: direct statement | K38: K1 (non-stationarity of the relationship); K2 (baseload or non-productive energy) | L38: destacada | N38: online re-estimation | O38: implemented | P38: implicit | U38: online re-estimation | V38: implemented | W38: implicit
A39: ADP-039 | B39: T3 | C39: rayyan-472535794 | D39: Giacone (2012) | E39: 2 | G39: D2 → paper-level argument | H39: The authors have recently made a contribution to this ﬁeld [21,22], by suggesting the use of the tabular CUSUM control chart. | I39: direct statement | J39: adaptation other: tabular CUSUM control chart to ensure the model refers to the most recent and stable period | K39: K1 (indicator not meaningful as defined); K2 (indicator not meaningful as defined); K3 (cross-site comparability); K4 (cross-site comparability); K5 (cross-site comparability); K6 (indicator not meaningful as defined); K7 (statistical misspecification); K8 (non-stationarity of the relationship); K9 (baseline drift or expiry); K10 (indicator not meaningful as defined); K11 (multi-product allocation) | L39: destacada | N39: other | O39: proposed | P39: absent | U39: other | V39: proposed | W39: absent
A40: ADP-040 | B40: T3 | C40: rayyan-472535794 | D40: Giacone (2012) | E40: 10 | G40: D3 → A2 | H40: it should be complemented with another indicator e for example, the variable consumption ratio k or the marginal consumption c1 e since, in general, SEC depends on the production rate. | I40: direct statement | J40: adaptation other: complement SEC with the variable consumption ratio k or the marginal consumption c1 to separate the production-rate effect | K40: K1 (indicator not meaningful as defined); K2 (indicator not meaningful as defined); K3 (cross-site comparability); K4 (cross-site comparability); K5 (cross-site comparability); K6 (indicator not meaningful as defined); K7 (statistical misspecification); K8 (non-stationarity of the relationship); K9 (baseline drift or expiry); K10 (indicator not meaningful as defined); K11 (multi-product allocation) | L40: destacada | N40: other | O40: implemented | P40: implicit | Q40: K1 | U40: other | V40: implemented | W40: implicit | X40: K1
...

Sheet MODELOS
A1: Nº | B1: Tier | C1: Artigo | D1: Autor (ano) | E1: Pág. | F1: Pág. corrigida? | G1: Modelo | H1: Campo | I1: Contexto | J1: Citação | K1: support_class | L1: Localização no PDF | M1: Citação sustenta? | N1: Valor | O1: Nota | P1: Verificado | Q1: orig_Valor
A2: MOD-001 | B2: T1 | C2: rayyan-472535351 | D2: Almanza (2025) | E2: 7 | G2: A1/M1 «the simulation model» | H2: C5 data_origin | I2: vetor: natural gas | J2: In the simulation model of the refinery’s cogeneration plant, the output data used to validate the model is the natural gas consumed by the set of seven boilers. | K2: requires inference | L2: destacada | N2: simulation | Q2: simulation
A3: MOD-002 | B3: T1 | C3: rayyan-472535351 | D3: Almanza (2025) | E3: 7 | G3: A1/M1 «the simulation model» | H3: C5 boundary | I3: vetor: natural gas | J3: In the simulation model of the refinery’s cogeneration plant, the output data used to validate the model is the natural gas consumed by the set of seven boilers. | K3: requires inference | L3: destacada | N3: exact | Q3: exact
A4: MOD-003 | B4: T1 | C4: rayyan-472535351 | D4: Almanza (2025) | E4: 7 | G4: A1/M1 «the simulation model» | H4: C8 OOS status | I4: design: not reported; métricas: correlation coefficient between real and simulated natural gas consumption=0.6408; median percentage difference (real vs simulated natural gas)=7.8% | J4: the correlation coefficient between real and simulated data is 0.6408, which is a strong correlation according to Cohen, cited by Lalinde et al. (2018). | K4: direct statement | L4: destacada | N4: reported | Q4: reported
A5: MOD-004 | B5: T1 | C5: rayyan-472535365 | D5: Moghadasi (2025) | E5: 10 | G5: A1/M1 «the Gradient Boosting Machines (GBM) algorithm / GBM predict» | H5: C5 data_origin | I5: vetor: steam | J5: The present study considered data collected between January 2020 and January 2021 from a gas refinery's Distributed Control System (DCS) plant at Iran's South Pars Gas Complex. | K5: requires inference | L5: destacada | N5: process historian tag | Q5: process historian tag
A6: MOD-005 | B6: T1 | C6: rayyan-472535365 | D6: Moghadasi (2025) | E6: 10 | G6: A1/M1 «the Gradient Boosting Machines (GBM) algorithm / GBM predict» | H6: C5 boundary | I6: vetor: steam | J6: The present study considered data collected between January 2020 and January 2021 from a gas refinery's Distributed Control System (DCS) plant at Iran's South Pars Gas Complex. | K6: requires inference | L6: destacada | N6: exact | Q6: exact
A7: MOD-006 | B7: T1 | C7: rayyan-472535365 | D7: Moghadasi (2025) | E7: 12 | G7: A1/M1 «the Gradient Boosting Machines (GBM) algorithm / GBM predict» | H7: C8 OOS status | I7: design: held-out split; métricas: R2 (validation set)=0.99; RMSE (validation set)=108.8; RMAE (validation set)=0.14 | J7: the GBM algorithm performed as a robust and high-accuracy model with R2 (validation set) = 0.99, RSME (validation set) = 108.8 kg.hr−1 and RMAE (validation set) = 0.14% at predicting the steam flow rate of the EDU. | K7: direct statement | L7: destacada | N7: reported | Q7: reported
A8: MOD-007 | B8: T4 | C8: rayyan-472535480 | D8: Andersson (2021) | E8: 4 | G8: A1/M1 «SEC for both electricity and heat ... for the entire mill» | H8: C7 statement | I8: bounds: the range of accepted values for the EnPIs monitored (the mill's 'normal state of operation'), defined individually for each mill and connected to a certain grade of pulp produced | J8: EnPIs for systems and flow level mainly serve to identify deviations from what is defined as a mill's normal state of operation, i.e. the range of accepted values for the EnPIs monitored. | K8: direct statement | L8: destacada | N8: stated qualitatively | Q8: stated qualitatively
A9: MOD-008 | B9: T4 | C9: rayyan-472535480 | D9: Andersson (2021) | E9: 6 | G9: A1/M2 «the steam demand per amount of black liquor dry solids» | H9: C7 statement | I9: bounds: dry content of weak black liquor ranging from 15% (normal) to 25% (theoretical); normal vs. best point of operation | J9: Normal operation refers to the most likely point of operation. Best operation refers to an optimal state of operation that is considered long enough to be steady-state. | K9: direct statement | L9: destacada | N9: stated qualitatively | Q9: stated qualitatively
A10: MOD-011 | B10: T1 | C10: rayyan-472535524 | D10: Beisheim (2020) | E10: 4 | G10: A1/M1 «the EnPI of the aggregated site» | H10: C5 data_origin | I10: vetor: steam | J10: These flows do not cross the system boundary and thus are not considered as products of the aggregated RMU. | K10: requires inference | L10: destacada | N10: calculated from process data | Q10: calculated from process data
A11: MOD-012 | B11: T1 | C11: rayyan-472535524 | D11: Beisheim (2020) | E11: 4 | G11: A1/M1 «the EnPI of the aggregated site» | H11: C5 boundary | I11: vetor: steam | J11: These flows do not cross the system boundary and thus are not considered as products of the aggregated RMU. | K11: requires inference | L11: destacada | N11: allocated by rule | Q11: allocated by rule
A12: MOD-009 | B12: T1 | C12: rayyan-472535524 | D12: Beisheim (2020) | E12: 7 | G12: A1/M1 «the EnPI of the aggregated site» | H12: C5 data_origin | I12: vetor: electricity | J12: The electric power and steam demands are covered by imports from the grid. | K12: requires inference | L12: destacada | N12: not reported | Q12: not reported
A13: MOD-010 | B13: T1 | C13: rayyan-472535524 | D13: Beisheim (2020) | E13: 7 | G13: A1/M1 «the EnPI of the aggregated site» | H13: C5 boundary | I13: vetor: electricity | J13: The electric power and steam demands are covered by imports from the grid. | K13: requires inference | L13: destacada | N13: exact | Q13: exact
... A133: MOD-132 | B133: T1 | C133: rayyan-472536695 | D133: Velázquez (2013) | E133: 7 | G133: A1/M1 «The regression model of SCPU» | H133: C5 boundary | I133: vetor: steam | J133: Many variables are measured and collected in the PU. | K133: requires inference | L133: destacada | N133: exact | Q133: exact

Sheet Tempos
A1: Artigo | B1: Autor (ano) | C1: Itens | D1: Itens T1 | E1: Minutos (preencher) | F1: Min/item
A2: rayyan-472535351 | B2: Almanza (2025) | C2: =COUNTIF(MEC!$C:$C,A2)+COUNTIF(ADP!$C:$C,A2)+COUNTIF(MODELOS!$C:$C,A2) -> 8 | D2: =COUNTIFS(MEC!$C:$C,A2,MEC!$B:$B,"T1")+COUNTIFS(ADP!$C:$C,A2,ADP!$B:$B,"T1")+COUNTIFS(MODELOS!$C:$C,A2,MODELOS!$B:$B,"T1") -> 8 | F2: =IF(E2="","",E2/C2)
A3: rayyan-472535365 | B3: Moghadasi (2025) | C3: =COUNTIF(MEC!$C:$C,A3)+COUNTIF(ADP!$C:$C,A3)+COUNTIF(MODELOS!$C:$C,A3) -> 8 | D3: =COUNTIFS(MEC!$C:$C,A3,MEC!$B:$B,"T1")+COUNTIFS(ADP!$C:$C,A3,ADP!$B:$B,"T1")+COUNTIFS(MODELOS!$C:$C,A3,MODELOS!$B:$B,"T1") -> 8 | F3: =IF(E3="","",E3/C3)
